Apr 07 13:44:29.94
GET
500
clipbaord-e6q518n10-kagabolucky72-gmailcoms-projects.vercel.app
/
ython.py", line 14, in <module> __vc_spec.loader.exec_module(__vc_module) File "<frozen importlib._bootstrap_external>", line 999, in exec_module File "<frozen importlib._bootstrap>", line 488, in _call_with_frames_removed File "/var/task/api/index.py", line 13, in <module> from web_app import app File "/var/task/web_app.py", line 33, in <module> db_manager = DatabaseManager() ^^^^^^^^^^^^^^^^^ File "/var/task/database.py", line 56, in __init__ Base.metadata.create_all(self.engine) File "/var/task/sqlalchemy/sql/schema.py", line 5925, in create_all bind._run_ddl_visitor( File "/var/task/sqlalchemy/engine/base.py", line 3248, in _run_ddl_visitor with self.begin() as conn: ^^^^^^^^^^^^ File "/var/lang/lib/python3.12/contextlib.py", line 137, in __enter__ return next(self.gen) ^^^^^^^^^^^^^^ File "/var/task/sqlalchemy/engine/base.py", line 3238, in begin with self.connect() as conn: ^^^^^^^^^^^^^^ File "/var/task/sqlalchemy/engine/base.py", line 3274, in connect return self._connection_cls(self) ^^^^^^^^^^^^^^^^^^^^^^^^^^ File "/var/task/sqlalchemy/engine/base.py", line 148, in __init__ Connection._handle_dbapi_exception_noconnection( File "/var/task/sqlalchemy/engine/base.py", line 2439, in _handle_dbapi_exception_noconnection raise sqlalchemy_exception.with_traceback(exc_info[2]) from e File "/var/task/sqlalchemy/engine/base.py", line 146, in __init__ self._dbapi_connection = engine.raw_connection() ^^^^^^^^^^^^^^^^^^^^^^^ File "/var/task/sqlalchemy/engine/base.py", line 3298, in raw_connection return self.pool.connect() ^^^^^^^^^^^^^^^^^^^ File "/var/task/sqlalchemy/pool/base.py", line 449, in connect return _ConnectionFairy._checkout(self) ^^^^^^^^^^^^^^^^^^^^^^^^^^^^^^^^ File "/var/task/sqlalchemy/pool/base.py", line 1264, in _checkout fairy = _ConnectionRecord.checkout(pool) ^^^^^^^^^^^^^^^^^^^^^^^^^^^^^^^^ File "/var/task/sqlalchemy/pool/base.py", line 713, in checkout rec = pool._do_get() ^^^^^^^^^^^^^^ File "/var/task/sqlalchemy/pool/impl.py", line 179, in _do_get with util.safe_reraise(): ^^^^^^^^^^^^^^^^^^^ File "/var/task/sqlalchemy/util/langhelpers.py", line 146, in __exit__ raise exc_value.with_traceback(exc_tb) File "/var/task/sqlalchemy/pool/impl.py", line 177, in _do_get return self._create_connection() ^^^^^^^^^^^^^^^^^^^^^^^^^ File "/var/task/sqlalchemy/pool/base.py", line 390, in _create_connection return _ConnectionRecord(self) ^^^^^^^^^^^^^^^^^^^^^^^ File "/var/task/sqlalchemy/pool/base.py", line 675, in __init__ self.__connect() File "/var/task/sqlalchemy/pool/base.py", line 901, in __connect with util.safe_reraise(): ^^^^^^^^^^^^^^^^^^^ File "/var/task/sqlalchemy/util/langhelpers.py", line 146, in __exit__ raise exc_value.with_traceback(exc_tb) File "/var/task/sqlalchemy/pool/base.py", line 897, in __connect self.dbapi_connection = connection = pool._invoke_creator(self) ^^^^^^^^^^^^^^^^^^^^^^^^^^ File "/var/task/sqlalchemy/engine/create.py", line 646, in connect return dialect.connect(*cargs, **cparams) ^^^^^^^^^^^^^^^^^^^^^^^^^^^^^^^^^^ File "/var/task/sqlalchemy/engine/default.py", line 625, in connect return self.loaded_dbapi.connect(*cargs, **cparams) # type: ignore[no-any-return] # NOQA: E501 ^^^^^^^^^^^^^^^^^^^^^^^^^^^^^^^^^^^^^^^^^^^^ File "/var/task/psycopg2/__init__.py", line 121, in connect dsn = _ext.make_dsn(dsn, **kwargs) ^^^^^^^^^^^^^^^^^^^^^^^^^^^^ File "/var/task/psycopg2/extensions.py", line 167, in make_dsn parse_dsn(dsn) sqlalchemy.exc.ProgrammingError: (psycopg2.ProgrammingError) invalid dsn: invalid connection option "supa" (Background on this error at: https://sqlalche.me/e/20/f405) Python process exited with exit status: 1. The logs above can help with debugging the issue.
Apr 07 13:44:17.61
GET
500
clipbaord-e6q518n10-kagabolucky72-gmailcoms-projects.vercel.app
/
ython.py", line 14, in <module> __vc_spec.loader.exec_module(__vc_module) File "<frozen importlib._bootstrap_external>", line 999, in exec_module File "<frozen importlib._bootstrap>", line 488, in _call_with_frames_removed File "/var/task/api/index.py", line 13, in <module> from web_app import app File "/var/task/web_app.py", line 33, in <module> db_manager = DatabaseManager() ^^^^^^^^^^^^^^^^^ File "/var/task/database.py", line 56, in __init__ Base.metadata.create_all(self.engine) File "/var/task/sqlalchemy/sql/schema.py", line 5925, in create_all bind._run_ddl_visitor( File "/var/task/sqlalchemy/engine/base.py", line 3248, in _run_ddl_visitor with self.begin() as conn: ^^^^^^^^^^^^ File "/var/lang/lib/python3.12/contextlib.py", line 137, in __enter__ return next(self.gen) ^^^^^^^^^^^^^^ File "/var/task/sqlalchemy/engine/base.py", line 3238, in begin with self.connect() as conn: ^^^^^^^^^^^^^^ File "/var/task/sqlalchemy/engine/base.py", line 3274, in connect return self._connection_cls(self) ^^^^^^^^^^^^^^^^^^^^^^^^^^ File "/var/task/sqlalchemy/engine/base.py", line 148, in __init__ Connection._handle_dbapi_exception_noconnection( File "/var/task/sqlalchemy/engine/base.py", line 2439, in _handle_dbapi_exception_noconnection raise sqlalchemy_exception.with_traceback(exc_info[2]) from e File "/var/task/sqlalchemy/engine/base.py", line 146, in __init__ self._dbapi_connection = engine.raw_connection() ^^^^^^^^^^^^^^^^^^^^^^^ File "/var/task/sqlalchemy/engine/base.py", line 3298, in raw_connection return self.pool.connect() ^^^^^^^^^^^^^^^^^^^ File "/var/task/sqlalchemy/pool/base.py", line 449, in connect return _ConnectionFairy._checkout(self) ^^^^^^^^^^^^^^^^^^^^^^^^^^^^^^^^ File "/var/task/sqlalchemy/pool/base.py", line 1264, in _checkout fairy = _ConnectionRecord.checkout(pool) ^^^^^^^^^^^^^^^^^^^^^^^^^^^^^^^^ File "/var/task/sqlalchemy/pool/base.py", line 713, in checkout rec = pool._do_get() ^^^^^^^^^^^^^^ File "/var/task/sqlalchemy/pool/impl.py", line 179, in _do_get with util.safe_reraise(): ^^^^^^^^^^^^^^^^^^^ File "/var/task/sqlalchemy/util/langhelpers.py", line 146, in __exit__ raise exc_value.with_traceback(exc_tb) File "/var/task/sqlalchemy/pool/impl.py", line 177, in _do_get return self._create_connection() ^^^^^^^^^^^^^^^^^^^^^^^^^ File "/var/task/sqlalchemy/pool/base.py", line 390, in _create_connection return _ConnectionRecord(self) ^^^^^^^^^^^^^^^^^^^^^^^ File "/var/task/sqlalchemy/pool/base.py", line 675, in __init__ self.__connect() File "/var/task/sqlalchemy/pool/base.py", line 901, in __connect with util.safe_reraise(): ^^^^^^^^^^^^^^^^^^^ File "/var/task/sqlalchemy/util/langhelpers.py", line 146, in __exit__ raise exc_value.with_traceback(exc_tb) File "/var/task/sqlalchemy/pool/base.py", line 897, in __connect self.dbapi_connection = connection = pool._invoke_creator(self) ^^^^^^^^^^^^^^^^^^^^^^^^^^ File "/var/task/sqlalchemy/engine/create.py", line 646, in connect return dialect.connect(*cargs, **cparams) ^^^^^^^^^^^^^^^^^^^^^^^^^^^^^^^^^^ File "/var/task/sqlalchemy/engine/default.py", line 625, in connect return self.loaded_dbapi.connect(*cargs, **cparams) # type: ignore[no-any-return] # NOQA: E501 ^^^^^^^^^^^^^^^^^^^^^^^^^^^^^^^^^^^^^^^^^^^^ File "/var/task/psycopg2/__init__.py", line 121, in connect dsn = _ext.make_dsn(dsn, **kwargs) ^^^^^^^^^^^^^^^^^^^^^^^^^^^^ File "/var/task/psycopg2/extensions.py", line 167, in make_dsn parse_dsn(dsn) sqlalchemy.exc.ProgrammingError: (psycopg2.ProgrammingError) invalid dsn: invalid connection option "supa" (Background on this error at: https://sqlalche.me/e/20/f405) Python process exited with exit status: 1. The logs above can help with debugging the issue.
Apr 07 13:44:15.90
GET
500
clipbaord-e6q518n10-kagabolucky72-gmailcoms-projects.vercel.app
/
ython.py", line 14, in <module> __vc_spec.loader.exec_module(__vc_module) File "<frozen importlib._bootstrap_external>", line 999, in exec_module File "<frozen importlib._bootstrap>", line 488, in _call_with_frames_removed File "/var/task/api/index.py", line 13, in <module> from web_app import app File "/var/task/web_app.py", line 33, in <module> db_manager = DatabaseManager() ^^^^^^^^^^^^^^^^^ File "/var/task/database.py", line 56, in __init__ Base.metadata.create_all(self.engine) File "/var/task/sqlalchemy/sql/schema.py", line 5925, in create_all bind._run_ddl_visitor( File "/var/task/sqlalchemy/engine/base.py", line 3248, in _run_ddl_visitor with self.begin() as conn: ^^^^^^^^^^^^ File "/var/lang/lib/python3.12/contextlib.py", line 137, in __enter__ return next(self.gen) ^^^^^^^^^^^^^^ File "/var/task/sqlalchemy/engine/base.py", line 3238, in begin with self.connect() as conn: ^^^^^^^^^^^^^^ File "/var/task/sqlalchemy/engine/base.py", line 3274, in connect return self._connection_cls(self) ^^^^^^^^^^^^^^^^^^^^^^^^^^ File "/var/task/sqlalchemy/engine/base.py", line 148, in __init__ Connection._handle_dbapi_exception_noconnection( File "/var/task/sqlalchemy/engine/base.py", line 2439, in _handle_dbapi_exception_noconnection raise sqlalchemy_exception.with_traceback(exc_info[2]) from e File "/var/task/sqlalchemy/engine/base.py", line 146, in __init__ self._dbapi_connection = engine.raw_connection() ^^^^^^^^^^^^^^^^^^^^^^^ File "/var/task/sqlalchemy/engine/base.py", line 3298, in raw_connection return self.pool.connect() ^^^^^^^^^^^^^^^^^^^ File "/var/task/sqlalchemy/pool/base.py", line 449, in connect return _ConnectionFairy._checkout(self) ^^^^^^^^^^^^^^^^^^^^^^^^^^^^^^^^ File "/var/task/sqlalchemy/pool/base.py", line 1264, in _checkout fairy = _ConnectionRecord.checkout(pool) ^^^^^^^^^^^^^^^^^^^^^^^^^^^^^^^^ File "/var/task/sqlalchemy/pool/base.py", line 713, in checkout rec = pool._do_get() ^^^^^^^^^^^^^^ File "/var/task/sqlalchemy/pool/impl.py", line 179, in _do_get with util.safe_reraise(): ^^^^^^^^^^^^^^^^^^^ File "/var/task/sqlalchemy/util/langhelpers.py", line 146, in __exit__ raise exc_value.with_traceback(exc_tb) File "/var/task/sqlalchemy/pool/impl.py", line 177, in _do_get return self._create_connection() ^^^^^^^^^^^^^^^^^^^^^^^^^ File "/var/task/sqlalchemy/pool/base.py", line 390, in _create_connection return _ConnectionRecord(self) ^^^^^^^^^^^^^^^^^^^^^^^ File "/var/task/sqlalchemy/pool/base.py", line 675, in __init__ self.__connect() File "/var/task/sqlalchemy/pool/base.py", line 901, in __connect with util.safe_reraise(): ^^^^^^^^^^^^^^^^^^^ File "/var/task/sqlalchemy/util/langhelpers.py", line 146, in __exit__ raise exc_value.with_traceback(exc_tb) File "/var/task/sqlalchemy/pool/base.py", line 897, in __connect self.dbapi_connection = connection = pool._invoke_creator(self) ^^^^^^^^^^^^^^^^^^^^^^^^^^ File "/var/task/sqlalchemy/engine/create.py", line 646, in connect return dialect.connect(*cargs, **cparams) ^^^^^^^^^^^^^^^^^^^^^^^^^^^^^^^^^^ File "/var/task/sqlalchemy/engine/default.py", line 625, in connect return self.loaded_dbapi.connect(*cargs, **cparams) # type: ignore[no-any-return] # NOQA: E501 ^^^^^^^^^^^^^^^^^^^^^^^^^^^^^^^^^^^^^^^^^^^^ File "/var/task/psycopg2/__init__.py", line 121, in connect dsn = _ext.make_dsn(dsn, **kwargs) ^^^^^^^^^^^^^^^^^^^^^^^^^^^^ File "/var/task/psycopg2/extensions.py", line 167, in make_dsn parse_dsn(dsn) sqlalchemy.exc.ProgrammingError: (psycopg2.ProgrammingError) invalid dsn: invalid connection option "supa" (Background on this error at: https://sqlalche.me/e/20/f405) Python process exited with exit status: 1. The logs above can help with debugging the issue.
Apr 07 13:44:13.97
GET
500
clipbaord-e6q518n10-kagabolucky72-gmailcoms-projects.vercel.app
/
ython.py", line 14, in <module> __vc_spec.loader.exec_module(__vc_module) File "<frozen importlib._bootstrap_external>", line 999, in exec_module File "<frozen importlib._bootstrap>", line 488, in _call_with_frames_removed File "/var/task/api/index.py", line 13, in <module> from web_app import app File "/var/task/web_app.py", line 33, in <module> db_manager = DatabaseManager() ^^^^^^^^^^^^^^^^^ File "/var/task/database.py", line 56, in __init__ Base.metadata.create_all(self.engine) File "/var/task/sqlalchemy/sql/schema.py", line 5925, in create_all bind._run_ddl_visitor( File "/var/task/sqlalchemy/engine/base.py", line 3248, in _run_ddl_visitor with self.begin() as conn: ^^^^^^^^^^^^ File "/var/lang/lib/python3.12/contextlib.py", line 137, in __enter__ return next(self.gen) ^^^^^^^^^^^^^^ File "/var/task/sqlalchemy/engine/base.py", line 3238, in begin with self.connect() as conn: ^^^^^^^^^^^^^^ File "/var/task/sqlalchemy/engine/base.py", line 3274, in connect return self._connection_cls(self) ^^^^^^^^^^^^^^^^^^^^^^^^^^ File "/var/task/sqlalchemy/engine/base.py", line 148, in __init__ Connection._handle_dbapi_exception_noconnection( File "/var/task/sqlalchemy/engine/base.py", line 2439, in _handle_dbapi_exception_noconnection raise sqlalchemy_exception.with_traceback(exc_info[2]) from e File "/var/task/sqlalchemy/engine/base.py", line 146, in __init__ self._dbapi_connection = engine.raw_connection() ^^^^^^^^^^^^^^^^^^^^^^^ File "/var/task/sqlalchemy/engine/base.py", line 3298, in raw_connection return self.pool.connect() ^^^^^^^^^^^^^^^^^^^ File "/var/task/sqlalchemy/pool/base.py", line 449, in connect return _ConnectionFairy._checkout(self) ^^^^^^^^^^^^^^^^^^^^^^^^^^^^^^^^ File "/var/task/sqlalchemy/pool/base.py", line 1264, in _checkout fairy = _ConnectionRecord.checkout(pool) ^^^^^^^^^^^^^^^^^^^^^^^^^^^^^^^^ File "/var/task/sqlalchemy/pool/base.py", line 713, in checkout rec = pool._do_get() ^^^^^^^^^^^^^^ File "/var/task/sqlalchemy/pool/impl.py", line 179, in _do_get with util.safe_reraise(): ^^^^^^^^^^^^^^^^^^^ File "/var/task/sqlalchemy/util/langhelpers.py", line 146, in __exit__ raise exc_value.with_traceback(exc_tb) File "/var/task/sqlalchemy/pool/impl.py", line 177, in _do_get return self._create_connection() ^^^^^^^^^^^^^^^^^^^^^^^^^ File "/var/task/sqlalchemy/pool/base.py", line 390, in _create_connection return _ConnectionRecord(self) ^^^^^^^^^^^^^^^^^^^^^^^ File "/var/task/sqlalchemy/pool/base.py", line 675, in __init__ self.__connect() File "/var/task/sqlalchemy/pool/base.py", line 901, in __connect with util.safe_reraise(): ^^^^^^^^^^^^^^^^^^^ File "/var/task/sqlalchemy/util/langhelpers.py", line 146, in __exit__ raise exc_value.with_traceback(exc_tb) File "/var/task/sqlalchemy/pool/base.py", line 897, in __connect self.dbapi_connection = connection = pool._invoke_creator(self) ^^^^^^^^^^^^^^^^^^^^^^^^^^ File "/var/task/sqlalchemy/engine/create.py", line 646, in connect return dialect.connect(*cargs, **cparams) ^^^^^^^^^^^^^^^^^^^^^^^^^^^^^^^^^^ File "/var/task/sqlalchemy/engine/default.py", line 625, in connect return self.loaded_dbapi.connect(*cargs, **cparams) # type: ignore[no-any-return] # NOQA: E501 ^^^^^^^^^^^^^^^^^^^^^^^^^^^^^^^^^^^^^^^^^^^^ File "/var/task/psycopg2/__init__.py", line 121, in connect dsn = _ext.make_dsn(dsn, **kwargs) ^^^^^^^^^^^^^^^^^^^^^^^^^^^^ File "/var/task/psycopg2/extensions.py", line 167, in make_dsn parse_dsn(dsn) sqlalchemy.exc.ProgrammingError: (psycopg2.ProgrammingError) invalid dsn: invalid connection option "supa" (Background on this error at: https://sqlalche.me/e/20/f405) Python process exited with exit status: 1. The logs above can help with debugging the issue.
Apr 07 13:44:13.33
GET
500
clipbaord-e6q518n10-kagabolucky72-gmailcoms-projects.vercel.app
/
ython.py", line 14, in <module> __vc_spec.loader.exec_module(__vc_module) File "<frozen importlib._bootstrap_external>", line 999, in exec_module File "<frozen importlib._bootstrap>", line 488, in _call_with_frames_removed File "/var/task/api/index.py", line 13, in <module> from web_app import app File "/var/task/web_app.py", line 33, in <module> db_manager = DatabaseManager() ^^^^^^^^^^^^^^^^^ File "/var/task/database.py", line 56, in __init__ Base.metadata.create_all(self.engine) File "/var/task/sqlalchemy/sql/schema.py", line 5925, in create_all bind._run_ddl_visitor( File "/var/task/sqlalchemy/engine/base.py", line 3248, in _run_ddl_visitor with self.begin() as conn: ^^^^^^^^^^^^ File "/var/lang/lib/python3.12/contextlib.py", line 137, in __enter__ return next(self.gen) ^^^^^^^^^^^^^^ File "/var/task/sqlalchemy/engine/base.py", line 3238, in begin with self.connect() as conn: ^^^^^^^^^^^^^^ File "/var/task/sqlalchemy/engine/base.py", line 3274, in connect return self._connection_cls(self) ^^^^^^^^^^^^^^^^^^^^^^^^^^ File "/var/task/sqlalchemy/engine/base.py", line 148, in __init__ Connection._handle_dbapi_exception_noconnection( File "/var/task/sqlalchemy/engine/base.py", line 2439, in _handle_dbapi_exception_noconnection raise sqlalchemy_exception.with_traceback(exc_info[2]) from e File "/var/task/sqlalchemy/engine/base.py", line 146, in __init__ self._dbapi_connection = engine.raw_connection() ^^^^^^^^^^^^^^^^^^^^^^^ File "/var/task/sqlalchemy/engine/base.py", line 3298, in raw_connection return self.pool.connect() ^^^^^^^^^^^^^^^^^^^ File "/var/task/sqlalchemy/pool/base.py", line 449, in connect return _ConnectionFairy._checkout(self) ^^^^^^^^^^^^^^^^^^^^^^^^^^^^^^^^ File "/var/task/sqlalchemy/pool/base.py", line 1264, in _checkout fairy = _ConnectionRecord.checkout(pool) ^^^^^^^^^^^^^^^^^^^^^^^^^^^^^^^^ File "/var/task/sqlalchemy/pool/base.py", line 713, in checkout rec = pool._do_get() ^^^^^^^^^^^^^^ File "/var/task/sqlalchemy/pool/impl.py", line 179, in _do_get with util.safe_reraise(): ^^^^^^^^^^^^^^^^^^^ File "/var/task/sqlalchemy/util/langhelpers.py", line 146, in __exit__ raise exc_value.with_traceback(exc_tb) File "/var/task/sqlalchemy/pool/impl.py", line 177, in _do_get return self._create_connection() ^^^^^^^^^^^^^^^^^^^^^^^^^ File "/var/task/sqlalchemy/pool/base.py", line 390, in _create_connection return _ConnectionRecord(self) ^^^^^^^^^^^^^^^^^^^^^^^ File "/var/task/sqlalchemy/pool/base.py", line 675, in __init__ self.__connect() File "/var/task/sqlalchemy/pool/base.py", line 901, in __connect with util.safe_reraise(): ^^^^^^^^^^^^^^^^^^^ File "/var/task/sqlalchemy/util/langhelpers.py", line 146, in __exit__ raise exc_value.with_traceback(exc_tb) File "/var/task/sqlalchemy/pool/base.py", line 897, in __connect self.dbapi_connection = connection = pool._invoke_creator(self) ^^^^^^^^^^^^^^^^^^^^^^^^^^ File "/var/task/sqlalchemy/engine/create.py", line 646, in connect return dialect.connect(*cargs, **cparams) ^^^^^^^^^^^^^^^^^^^^^^^^^^^^^^^^^^ File "/var/task/sqlalchemy/engine/default.py", line 625, in connect return self.loaded_dbapi.connect(*cargs, **cparams) # type: ignore[no-any-return] # NOQA: E501 ^^^^^^^^^^^^^^^^^^^^^^^^^^^^^^^^^^^^^^^^^^^^ File "/var/task/psycopg2/__init__.py", line 121, in connect dsn = _ext.make_dsn(dsn, **kwargs) ^^^^^^^^^^^^^^^^^^^^^^^^^^^^ File "/var/task/psycopg2/extensions.py", line 167, in make_dsn parse_dsn(dsn) sqlalchemy.exc.ProgrammingError: (psycopg2.ProgrammingError) invalid dsn: invalid connection option "supa" (Background on this error at: https://sqlalche.me/e/20/f405) Python process exited with exit status: 1. The logs above can help with debugging the issue.
Apr 07 13:44:10.94
GET
500
clipbaord-e6q518n10-kagabolucky72-gmailcoms-projects.vercel.app
/
ython.py", line 14, in <module> __vc_spec.loader.exec_module(__vc_module) File "<frozen importlib._bootstrap_external>", line 999, in exec_module File "<frozen importlib._bootstrap>", line 488, in _call_with_frames_removed File "/var/task/api/index.py", line 13, in <module> from web_app import app File "/var/task/web_app.py", line 33, in <module> db_manager = DatabaseManager() ^^^^^^^^^^^^^^^^^ File "/var/task/database.py", line 56, in __init__ Base.metadata.create_all(self.engine) File "/var/task/sqlalchemy/sql/schema.py", line 5925, in create_all bind._run_ddl_visitor( File "/var/task/sqlalchemy/engine/base.py", line 3248, in _run_ddl_visitor with self.begin() as conn: ^^^^^^^^^^^^ File "/var/lang/lib/python3.12/contextlib.py", line 137, in __enter__ return next(self.gen) ^^^^^^^^^^^^^^ File "/var/task/sqlalchemy/engine/base.py", line 3238, in begin with self.connect() as conn: ^^^^^^^^^^^^^^ File "/var/task/sqlalchemy/engine/base.py", line 3274, in connect return self._connection_cls(self) ^^^^^^^^^^^^^^^^^^^^^^^^^^ File "/var/task/sqlalchemy/engine/base.py", line 148, in __init__ Connection._handle_dbapi_exception_noconnection( File "/var/task/sqlalchemy/engine/base.py", line 2439, in _handle_dbapi_exception_noconnection raise sqlalchemy_exception.with_traceback(exc_info[2]) from e File "/var/task/sqlalchemy/engine/base.py", line 146, in __init__ self._dbapi_connection = engine.raw_connection() ^^^^^^^^^^^^^^^^^^^^^^^ File "/var/task/sqlalchemy/engine/base.py", line 3298, in raw_connection return self.pool.connect() ^^^^^^^^^^^^^^^^^^^ File "/var/task/sqlalchemy/pool/base.py", line 449, in connect return _ConnectionFairy._checkout(self) ^^^^^^^^^^^^^^^^^^^^^^^^^^^^^^^^ File "/var/task/sqlalchemy/pool/base.py", line 1264, in _checkout fairy = _ConnectionRecord.checkout(pool) ^^^^^^^^^^^^^^^^^^^^^^^^^^^^^^^^ File "/var/task/sqlalchemy/pool/base.py", line 713, in checkout rec = pool._do_get() ^^^^^^^^^^^^^^ File "/var/task/sqlalchemy/pool/impl.py", line 179, in _do_get with util.safe_reraise(): ^^^^^^^^^^^^^^^^^^^ File "/var/task/sqlalchemy/util/langhelpers.py", line 146, in __exit__ raise exc_value.with_traceback(exc_tb) File "/var/task/sqlalchemy/pool/impl.py", line 177, in _do_get return self._create_connection() ^^^^^^^^^^^^^^^^^^^^^^^^^ File "/var/task/sqlalchemy/pool/base.py", line 390, in _create_connection return _ConnectionRecord(self) ^^^^^^^^^^^^^^^^^^^^^^^ File "/var/task/sqlalchemy/pool/base.py", line 675, in __init__ self.__connect() File "/var/task/sqlalchemy/pool/base.py", line 901, in __connect with util.safe_reraise(): ^^^^^^^^^^^^^^^^^^^ File "/var/task/sqlalchemy/util/langhelpers.py", line 146, in __exit__ raise exc_value.with_traceback(exc_tb) File "/var/task/sqlalchemy/pool/base.py", line 897, in __connect self.dbapi_connection = connection = pool._invoke_creator(self) ^^^^^^^^^^^^^^^^^^^^^^^^^^ File "/var/task/sqlalchemy/engine/create.py", line 646, in connect return dialect.connect(*cargs, **cparams) ^^^^^^^^^^^^^^^^^^^^^^^^^^^^^^^^^^ File "/var/task/sqlalchemy/engine/default.py", line 625, in connect return self.loaded_dbapi.connect(*cargs, **cparams) # type: ignore[no-any-return] # NOQA: E501 ^^^^^^^^^^^^^^^^^^^^^^^^^^^^^^^^^^^^^^^^^^^^ File "/var/task/psycopg2/__init__.py", line 121, in connect dsn = _ext.make_dsn(dsn, **kwargs) ^^^^^^^^^^^^^^^^^^^^^^^^^^^^ File "/var/task/psycopg2/extensions.py", line 167, in make_dsn parse_dsn(dsn) sqlalchemy.exc.ProgrammingError: (psycopg2.ProgrammingError) invalid dsn: invalid connection option "supa" (Background on this error at: https://sqlalche.me/e/20/f405) Python process exited with exit status: 1. The logs above can help with debugging the issue.
Apr 07 13:44:10.89
GET
500
clipbaord-e6q518n10-kagabolucky72-gmailcoms-projects.vercel.app
/
ython.py", line 14, in <module> __vc_spec.loader.exec_module(__vc_module) File "<frozen importlib._bootstrap_external>", line 999, in exec_module File "<frozen importlib._bootstrap>", line 488, in _call_with_frames_removed File "/var/task/api/index.py", line 13, in <module> from web_app import app File "/var/task/web_app.py", line 33, in <module> db_manager = DatabaseManager() ^^^^^^^^^^^^^^^^^ File "/var/task/database.py", line 56, in __init__ Base.metadata.create_all(self.engine) File "/var/task/sqlalchemy/sql/schema.py", line 5925, in create_all bind._run_ddl_visitor( File "/var/task/sqlalchemy/engine/base.py", line 3248, in _run_ddl_visitor with self.begin() as conn: ^^^^^^^^^^^^ File "/var/lang/lib/python3.12/contextlib.py", line 137, in __enter__ return next(self.gen) ^^^^^^^^^^^^^^ File "/var/task/sqlalchemy/engine/base.py", line 3238, in begin with self.connect() as conn: ^^^^^^^^^^^^^^ File "/var/task/sqlalchemy/engine/base.py", line 3274, in connect return self._connection_cls(self) ^^^^^^^^^^^^^^^^^^^^^^^^^^ File "/var/task/sqlalchemy/engine/base.py", line 148, in __init__ Connection._handle_dbapi_exception_noconnection( File "/var/task/sqlalchemy/engine/base.py", line 2439, in _handle_dbapi_exception_noconnection raise sqlalchemy_exception.with_traceback(exc_info[2]) from e File "/var/task/sqlalchemy/engine/base.py", line 146, in __init__ self._dbapi_connection = engine.raw_connection() ^^^^^^^^^^^^^^^^^^^^^^^ File "/var/task/sqlalchemy/engine/base.py", line 3298, in raw_connection return self.pool.connect() ^^^^^^^^^^^^^^^^^^^ File "/var/task/sqlalchemy/pool/base.py", line 449, in connect return _ConnectionFairy._checkout(self) ^^^^^^^^^^^^^^^^^^^^^^^^^^^^^^^^ File "/var/task/sqlalchemy/pool/base.py", line 1264, in _checkout fairy = _ConnectionRecord.checkout(pool) ^^^^^^^^^^^^^^^^^^^^^^^^^^^^^^^^ File "/var/task/sqlalchemy/pool/base.py", line 713, in checkout rec = pool._do_get() ^^^^^^^^^^^^^^ File "/var/task/sqlalchemy/pool/impl.py", line 179, in _do_get with util.safe_reraise(): ^^^^^^^^^^^^^^^^^^^ File "/var/task/sqlalchemy/util/langhelpers.py", line 146, in __exit__ raise exc_value.with_traceback(exc_tb) File "/var/task/sqlalchemy/pool/impl.py", line 177, in _do_get return self._create_connection() ^^^^^^^^^^^^^^^^^^^^^^^^^ File "/var/task/sqlalchemy/pool/base.py", line 390, in _create_connection return _ConnectionRecord(self) ^^^^^^^^^^^^^^^^^^^^^^^ File "/var/task/sqlalchemy/pool/base.py", line 675, in __init__ self.__connect() File "/var/task/sqlalchemy/pool/base.py", line 901, in __connect with util.safe_reraise(): ^^^^^^^^^^^^^^^^^^^ File "/var/task/sqlalchemy/util/langhelpers.py", line 146, in __exit__ raise exc_value.with_traceback(exc_tb) File "/var/task/sqlalchemy/pool/base.py", line 897, in __connect self.dbapi_connection = connection = pool._invoke_creator(self) ^^^^^^^^^^^^^^^^^^^^^^^^^^ File "/var/task/sqlalchemy/engine/create.py", line 646, in connect return dialect.connect(*cargs, **cparams) ^^^^^^^^^^^^^^^^^^^^^^^^^^^^^^^^^^ File "/var/task/sqlalchemy/engine/default.py", line 625, in connect return self.loaded_dbapi.connect(*cargs, **cparams) # type: ignore[no-any-return] # NOQA: E501 ^^^^^^^^^^^^^^^^^^^^^^^^^^^^^^^^^^^^^^^^^^^^ File "/var/task/psycopg2/__init__.py", line 121, in connect dsn = _ext.make_dsn(dsn, **kwargs) ^^^^^^^^^^^^^^^^^^^^^^^^^^^^ File "/var/task/psycopg2/extensions.py", line 167, in make_dsn parse_dsn(dsn) sqlalchemy.exc.ProgrammingError: (psycopg2.ProgrammingError) invalid dsn: invalid connection option "supa" (Background on this error at: https://sqlalche.me/e/20/f405) Python process exited with exit status: 1. The logs above can help with debugging the issue.
Apr 07 13:44:09.61
GET
500
clipbaord-e6q518n10-kagabolucky72-gmailcoms-projects.vercel.app
/
ython.py", line 14, in <module> __vc_spec.loader.exec_module(__vc_module) File "<frozen importlib._bootstrap_external>", line 999, in exec_module File "<frozen importlib._bootstrap>", line 488, in _call_with_frames_removed File "/var/task/api/index.py", line 13, in <module> from web_app import app File "/var/task/web_app.py", line 33, in <module> db_manager = DatabaseManager() ^^^^^^^^^^^^^^^^^ File "/var/task/database.py", line 56, in __init__ Base.metadata.create_all(self.engine) File "/var/task/sqlalchemy/sql/schema.py", line 5925, in create_all bind._run_ddl_visitor( File "/var/task/sqlalchemy/engine/base.py", line 3248, in _run_ddl_visitor with self.begin() as conn: ^^^^^^^^^^^^ File "/var/lang/lib/python3.12/contextlib.py", line 137, in __enter__ return next(self.gen) ^^^^^^^^^^^^^^ File "/var/task/sqlalchemy/engine/base.py", line 3238, in begin with self.connect() as conn: ^^^^^^^^^^^^^^ File "/var/task/sqlalchemy/engine/base.py", line 3274, in connect return self._connection_cls(self) ^^^^^^^^^^^^^^^^^^^^^^^^^^ File "/var/task/sqlalchemy/engine/base.py", line 148, in __init__ Connection._handle_dbapi_exception_noconnection( File "/var/task/sqlalchemy/engine/base.py", line 2439, in _handle_dbapi_exception_noconnection raise sqlalchemy_exception.with_traceback(exc_info[2]) from e File "/var/task/sqlalchemy/engine/base.py", line 146, in __init__ self._dbapi_connection = engine.raw_connection() ^^^^^^^^^^^^^^^^^^^^^^^ File "/var/task/sqlalchemy/engine/base.py", line 3298, in raw_connection return self.pool.connect() ^^^^^^^^^^^^^^^^^^^ File "/var/task/sqlalchemy/pool/base.py", line 449, in connect return _ConnectionFairy._checkout(self) ^^^^^^^^^^^^^^^^^^^^^^^^^^^^^^^^ File "/var/task/sqlalchemy/pool/base.py", line 1264, in _checkout fairy = _ConnectionRecord.checkout(pool) ^^^^^^^^^^^^^^^^^^^^^^^^^^^^^^^^ File "/var/task/sqlalchemy/pool/base.py", line 713, in checkout rec = pool._do_get() ^^^^^^^^^^^^^^ File "/var/task/sqlalchemy/pool/impl.py", line 179, in _do_get with util.safe_reraise(): ^^^^^^^^^^^^^^^^^^^ File "/var/task/sqlalchemy/util/langhelpers.py", line 146, in __exit__ raise exc_value.with_traceback(exc_tb) File "/var/task/sqlalchemy/pool/impl.py", line 177, in _do_get return self._create_connection() ^^^^^^^^^^^^^^^^^^^^^^^^^ File "/var/task/sqlalchemy/pool/base.py", line 390, in _create_connection return _ConnectionRecord(self) ^^^^^^^^^^^^^^^^^^^^^^^ File "/var/task/sqlalchemy/pool/base.py", line 675, in __init__ self.__connect() File "/var/task/sqlalchemy/pool/base.py", line 901, in __connect with util.safe_reraise(): ^^^^^^^^^^^^^^^^^^^ File "/var/task/sqlalchemy/util/langhelpers.py", line 146, in __exit__ raise exc_value.with_traceback(exc_tb) File "/var/task/sqlalchemy/pool/base.py", line 897, in __connect self.dbapi_connection = connection = pool._invoke_creator(self) ^^^^^^^^^^^^^^^^^^^^^^^^^^ File "/var/task/sqlalchemy/engine/create.py", line 646, in connect return dialect.connect(*cargs, **cparams) ^^^^^^^^^^^^^^^^^^^^^^^^^^^^^^^^^^ File "/var/task/sqlalchemy/engine/default.py", line 625, in connect return self.loaded_dbapi.connect(*cargs, **cparams) # type: ignore[no-any-return] # NOQA: E501 ^^^^^^^^^^^^^^^^^^^^^^^^^^^^^^^^^^^^^^^^^^^^ File "/var/task/psycopg2/__init__.py", line 121, in connect dsn = _ext.make_dsn(dsn, **kwargs) ^^^^^^^^^^^^^^^^^^^^^^^^^^^^ File "/var/task/psycopg2/extensions.py", line 167, in make_dsn parse_dsn(dsn) sqlalchemy.exc.ProgrammingError: (psycopg2.ProgrammingError) invalid dsn: invalid connection option "supa" (Background on this error at: https://sqlalche.me/e/20/f405) Python process exited with exit status: 1. The logs above can help with debugging the issue.
Apr 07 13:44:07.12
GET
500
clipbaord-e6q518n10-kagabolucky72-gmailcoms-projects.vercel.app
/
ython.py", line 14, in <module> __vc_spec.loader.exec_module(__vc_module) File "<frozen importlib._bootstrap_external>", line 999, in exec_module File "<frozen importlib._bootstrap>", line 488, in _call_with_frames_removed File "/var/task/api/index.py", line 13, in <module> from web_app import app File "/var/task/web_app.py", line 33, in <module> db_manager = DatabaseManager() ^^^^^^^^^^^^^^^^^ File "/var/task/database.py", line 56, in __init__ Base.metadata.create_all(self.engine) File "/var/task/sqlalchemy/sql/schema.py", line 5925, in create_all bind._run_ddl_visitor( File "/var/task/sqlalchemy/engine/base.py", line 3248, in _run_ddl_visitor with self.begin() as conn: ^^^^^^^^^^^^ File "/var/lang/lib/python3.12/contextlib.py", line 137, in __enter__ return next(self.gen) ^^^^^^^^^^^^^^ File "/var/task/sqlalchemy/engine/base.py", line 3238, in begin with self.connect() as conn: ^^^^^^^^^^^^^^ File "/var/task/sqlalchemy/engine/base.py", line 3274, in connect return self._connection_cls(self) ^^^^^^^^^^^^^^^^^^^^^^^^^^ File "/var/task/sqlalchemy/engine/base.py", line 148, in __init__ Connection._handle_dbapi_exception_noconnection( File "/var/task/sqlalchemy/engine/base.py", line 2439, in _handle_dbapi_exception_noconnection raise sqlalchemy_exception.with_traceback(exc_info[2]) from e File "/var/task/sqlalchemy/engine/base.py", line 146, in __init__ self._dbapi_connection = engine.raw_connection() ^^^^^^^^^^^^^^^^^^^^^^^ File "/var/task/sqlalchemy/engine/base.py", line 3298, in raw_connection return self.pool.connect() ^^^^^^^^^^^^^^^^^^^ File "/var/task/sqlalchemy/pool/base.py", line 449, in connect return _ConnectionFairy._checkout(self) ^^^^^^^^^^^^^^^^^^^^^^^^^^^^^^^^ File "/var/task/sqlalchemy/pool/base.py", line 1264, in _checkout fairy = _ConnectionRecord.checkout(pool) ^^^^^^^^^^^^^^^^^^^^^^^^^^^^^^^^ File "/var/task/sqlalchemy/pool/base.py", line 713, in checkout rec = pool._do_get() ^^^^^^^^^^^^^^ File "/var/task/sqlalchemy/pool/impl.py", line 179, in _do_get with util.safe_reraise(): ^^^^^^^^^^^^^^^^^^^ File "/var/task/sqlalchemy/util/langhelpers.py", line 146, in __exit__ raise exc_value.with_traceback(exc_tb) File "/var/task/sqlalchemy/pool/impl.py", line 177, in _do_get return self._create_connection() ^^^^^^^^^^^^^^^^^^^^^^^^^ File "/var/task/sqlalchemy/pool/base.py", line 390, in _create_connection return _ConnectionRecord(self) ^^^^^^^^^^^^^^^^^^^^^^^ File "/var/task/sqlalchemy/pool/base.py", line 675, in __init__ self.__connect() File "/var/task/sqlalchemy/pool/base.py", line 901, in __connect with util.safe_reraise(): ^^^^^^^^^^^^^^^^^^^ File "/var/task/sqlalchemy/util/langhelpers.py", line 146, in __exit__ raise exc_value.with_traceback(exc_tb) File "/var/task/sqlalchemy/pool/base.py", line 897, in __connect self.dbapi_connection = connection = pool._invoke_creator(self) ^^^^^^^^^^^^^^^^^^^^^^^^^^ File "/var/task/sqlalchemy/engine/create.py", line 646, in connect return dialect.connect(*cargs, **cparams) ^^^^^^^^^^^^^^^^^^^^^^^^^^^^^^^^^^ File "/var/task/sqlalchemy/engine/default.py", line 625, in connect return self.loaded_dbapi.connect(*cargs, **cparams) # type: ignore[no-any-return] # NOQA: E501 ^^^^^^^^^^^^^^^^^^^^^^^^^^^^^^^^^^^^^^^^^^^^ File "/var/task/psycopg2/__init__.py", line 121, in connect dsn = _ext.make_dsn(dsn, **kwargs) ^^^^^^^^^^^^^^^^^^^^^^^^^^^^ File "/var/task/psycopg2/extensions.py", line 167, in make_dsn parse_dsn(dsn) sqlalchemy.exc.ProgrammingError: (psycopg2.ProgrammingError) invalid dsn: invalid connection option "supa" (Background on this error at: https://sqlalche.me/e/20/f405) Python process exited with exit status: 1. The logs above can help with debugging the issue.
Apr 07 13:44:06.90
GET
500
clipbaord-e6q518n10-kagabolucky72-gmailcoms-projects.vercel.app
/
ython.py", line 14, in <module> __vc_spec.loader.exec_module(__vc_module) File "<frozen importlib._bootstrap_external>", line 999, in exec_module File "<frozen importlib._bootstrap>", line 488, in _call_with_frames_removed File "/var/task/api/index.py", line 13, in <module> from web_app import app File "/var/task/web_app.py", line 33, in <module> db_manager = DatabaseManager() ^^^^^^^^^^^^^^^^^ File "/var/task/database.py", line 56, in __init__ Base.metadata.create_all(self.engine) File "/var/task/sqlalchemy/sql/schema.py", line 5925, in create_all bind._run_ddl_visitor( File "/var/task/sqlalchemy/engine/base.py", line 3248, in _run_ddl_visitor with self.begin() as conn: ^^^^^^^^^^^^ File "/var/lang/lib/python3.12/contextlib.py", line 137, in __enter__ return next(self.gen) ^^^^^^^^^^^^^^ File "/var/task/sqlalchemy/engine/base.py", line 3238, in begin with self.connect() as conn: ^^^^^^^^^^^^^^ File "/var/task/sqlalchemy/engine/base.py", line 3274, in connect return self._connection_cls(self) ^^^^^^^^^^^^^^^^^^^^^^^^^^ File "/var/task/sqlalchemy/engine/base.py", line 148, in __init__ Connection._handle_dbapi_exception_noconnection( File "/var/task/sqlalchemy/engine/base.py", line 2439, in _handle_dbapi_exception_noconnection raise sqlalchemy_exception.with_traceback(exc_info[2]) from e File "/var/task/sqlalchemy/engine/base.py", line 146, in __init__ self._dbapi_connection = engine.raw_connection() ^^^^^^^^^^^^^^^^^^^^^^^ File "/var/task/sqlalchemy/engine/base.py", line 3298, in raw_connection return self.pool.connect() ^^^^^^^^^^^^^^^^^^^ File "/var/task/sqlalchemy/pool/base.py", line 449, in connect return _ConnectionFairy._checkout(self) ^^^^^^^^^^^^^^^^^^^^^^^^^^^^^^^^ File "/var/task/sqlalchemy/pool/base.py", line 1264, in _checkout fairy = _ConnectionRecord.checkout(pool) ^^^^^^^^^^^^^^^^^^^^^^^^^^^^^^^^ File "/var/task/sqlalchemy/pool/base.py", line 713, in checkout rec = pool._do_get() ^^^^^^^^^^^^^^ File "/var/task/sqlalchemy/pool/impl.py", line 179, in _do_get with util.safe_reraise(): ^^^^^^^^^^^^^^^^^^^ File "/var/task/sqlalchemy/util/langhelpers.py", line 146, in __exit__ raise exc_value.with_traceback(exc_tb) File "/var/task/sqlalchemy/pool/impl.py", line 177, in _do_get return self._create_connection() ^^^^^^^^^^^^^^^^^^^^^^^^^ File "/var/task/sqlalchemy/pool/base.py", line 390, in _create_connection return _ConnectionRecord(self) ^^^^^^^^^^^^^^^^^^^^^^^ File "/var/task/sqlalchemy/pool/base.py", line 675, in __init__ self.__connect() File "/var/task/sqlalchemy/pool/base.py", line 901, in __connect with util.safe_reraise(): ^^^^^^^^^^^^^^^^^^^ File "/var/task/sqlalchemy/util/langhelpers.py", line 146, in __exit__ raise exc_value.with_traceback(exc_tb) File "/var/task/sqlalchemy/pool/base.py", line 897, in __connect self.dbapi_connection = connection = pool._invoke_creator(self) ^^^^^^^^^^^^^^^^^^^^^^^^^^ File "/var/task/sqlalchemy/engine/create.py", line 646, in connect return dialect.connect(*cargs, **cparams) ^^^^^^^^^^^^^^^^^^^^^^^^^^^^^^^^^^ File "/var/task/sqlalchemy/engine/default.py", line 625, in connect return self.loaded_dbapi.connect(*cargs, **cparams) # type: ignore[no-any-return] # NOQA: E501 ^^^^^^^^^^^^^^^^^^^^^^^^^^^^^^^^^^^^^^^^^^^^ File "/var/task/psycopg2/__init__.py", line 121, in connect dsn = _ext.make_dsn(dsn, **kwargs) ^^^^^^^^^^^^^^^^^^^^^^^^^^^^ File "/var/task/psycopg2/extensions.py", line 167, in make_dsn parse_dsn(dsn) sqlalchemy.exc.ProgrammingError: (psycopg2.ProgrammingError) invalid dsn: invalid connection option "supa" (Background on this error at: https://sqlalche.me/e/20/f405) Python process exited with exit status: 1. The logs above can help with debugging the issue.
Apr 07 13:44:04.76
GET
500
clipbaord-e6q518n10-kagabolucky72-gmailcoms-projects.vercel.app
/
ython.py", line 14, in <module> __vc_spec.loader.exec_module(__vc_module) File "<frozen importlib._bootstrap_external>", line 999, in exec_module File "<frozen importlib._bootstrap>", line 488, in _call_with_frames_removed File "/var/task/api/index.py", line 13, in <module> from web_app import app File "/var/task/web_app.py", line 33, in <module> db_manager = DatabaseManager() ^^^^^^^^^^^^^^^^^ File "/var/task/database.py", line 56, in __init__ Base.metadata.create_all(self.engine) File "/var/task/sqlalchemy/sql/schema.py", line 5925, in create_all bind._run_ddl_visitor( File "/var/task/sqlalchemy/engine/base.py", line 3248, in _run_ddl_visitor with self.begin() as conn: ^^^^^^^^^^^^ File "/var/lang/lib/python3.12/contextlib.py", line 137, in __enter__ return next(self.gen) ^^^^^^^^^^^^^^ File "/var/task/sqlalchemy/engine/base.py", line 3238, in begin with self.connect() as conn: ^^^^^^^^^^^^^^ File "/var/task/sqlalchemy/engine/base.py", line 3274, in connect return self._connection_cls(self) ^^^^^^^^^^^^^^^^^^^^^^^^^^ File "/var/task/sqlalchemy/engine/base.py", line 148, in __init__ Connection._handle_dbapi_exception_noconnection( File "/var/task/sqlalchemy/engine/base.py", line 2439, in _handle_dbapi_exception_noconnection raise sqlalchemy_exception.with_traceback(exc_info[2]) from e File "/var/task/sqlalchemy/engine/base.py", line 146, in __init__ self._dbapi_connection = engine.raw_connection() ^^^^^^^^^^^^^^^^^^^^^^^ File "/var/task/sqlalchemy/engine/base.py", line 3298, in raw_connection return self.pool.connect() ^^^^^^^^^^^^^^^^^^^ File "/var/task/sqlalchemy/pool/base.py", line 449, in connect return _ConnectionFairy._checkout(self) ^^^^^^^^^^^^^^^^^^^^^^^^^^^^^^^^ File "/var/task/sqlalchemy/pool/base.py", line 1264, in _checkout fairy = _ConnectionRecord.checkout(pool) ^^^^^^^^^^^^^^^^^^^^^^^^^^^^^^^^ File "/var/task/sqlalchemy/pool/base.py", line 713, in checkout rec = pool._do_get() ^^^^^^^^^^^^^^ File "/var/task/sqlalchemy/pool/impl.py", line 179, in _do_get with util.safe_reraise(): ^^^^^^^^^^^^^^^^^^^ File "/var/task/sqlalchemy/util/langhelpers.py", line 146, in __exit__ raise exc_value.with_traceback(exc_tb) File "/var/task/sqlalchemy/pool/impl.py", line 177, in _do_get return self._create_connection() ^^^^^^^^^^^^^^^^^^^^^^^^^ File "/var/task/sqlalchemy/pool/base.py", line 390, in _create_connection return _ConnectionRecord(self) ^^^^^^^^^^^^^^^^^^^^^^^ File "/var/task/sqlalchemy/pool/base.py", line 675, in __init__ self.__connect() File "/var/task/sqlalchemy/pool/base.py", line 901, in __connect with util.safe_reraise(): ^^^^^^^^^^^^^^^^^^^ File "/var/task/sqlalchemy/util/langhelpers.py", line 146, in __exit__ raise exc_value.with_traceback(exc_tb) File "/var/task/sqlalchemy/pool/base.py", line 897, in __connect self.dbapi_connection = connection = pool._invoke_creator(self) ^^^^^^^^^^^^^^^^^^^^^^^^^^ File "/var/task/sqlalchemy/engine/create.py", line 646, in connect return dialect.connect(*cargs, **cparams) ^^^^^^^^^^^^^^^^^^^^^^^^^^^^^^^^^^ File "/var/task/sqlalchemy/engine/default.py", line 625, in connect return self.loaded_dbapi.connect(*cargs, **cparams) # type: ignore[no-any-return] # NOQA: E501 ^^^^^^^^^^^^^^^^^^^^^^^^^^^^^^^^^^^^^^^^^^^^ File "/var/task/psycopg2/__init__.py", line 121, in connect dsn = _ext.make_dsn(dsn, **kwargs) ^^^^^^^^^^^^^^^^^^^^^^^^^^^^ File "/var/task/psycopg2/extensions.py", line 167, in make_dsn parse_dsn(dsn) sqlalchemy.exc.ProgrammingError: (psycopg2.ProgrammingError) invalid dsn: invalid connection option "supa" (Background on this error at: https://sqlalche.me/e/20/f405) Python process exited with exit status: 1. The logs above can help with debugging the issue.
Apr 07 13:44:04.61
GET
500
clipbaord-e6q518n10-kagabolucky72-gmailcoms-projects.vercel.app
/
ython.py", line 14, in <module> __vc_spec.loader.exec_module(__vc_module) File "<frozen importlib._bootstrap_external>", line 999, in exec_module File "<frozen importlib._bootstrap>", line 488, in _call_with_frames_removed File "/var/task/api/index.py", line 13, in <module> from web_app import app File "/var/task/web_app.py", line 33, in <module> db_manager = DatabaseManager() ^^^^^^^^^^^^^^^^^ File "/var/task/database.py", line 56, in __init__ Base.metadata.create_all(self.engine) File "/var/task/sqlalchemy/sql/schema.py", line 5925, in create_all bind._run_ddl_visitor( File "/var/task/sqlalchemy/engine/base.py", line 3248, in _run_ddl_visitor with self.begin() as conn: ^^^^^^^^^^^^ File "/var/lang/lib/python3.12/contextlib.py", line 137, in __enter__ return next(self.gen) ^^^^^^^^^^^^^^ File "/var/task/sqlalchemy/engine/base.py", line 3238, in begin with self.connect() as conn: ^^^^^^^^^^^^^^ File "/var/task/sqlalchemy/engine/base.py", line 3274, in connect return self._connection_cls(self) ^^^^^^^^^^^^^^^^^^^^^^^^^^ File "/var/task/sqlalchemy/engine/base.py", line 148, in __init__ Connection._handle_dbapi_exception_noconnection( File "/var/task/sqlalchemy/engine/base.py", line 2439, in _handle_dbapi_exception_noconnection raise sqlalchemy_exception.with_traceback(exc_info[2]) from e File "/var/task/sqlalchemy/engine/base.py", line 146, in __init__ self._dbapi_connection = engine.raw_connection() ^^^^^^^^^^^^^^^^^^^^^^^ File "/var/task/sqlalchemy/engine/base.py", line 3298, in raw_connection return self.pool.connect() ^^^^^^^^^^^^^^^^^^^ File "/var/task/sqlalchemy/pool/base.py", line 449, in connect return _ConnectionFairy._checkout(self) ^^^^^^^^^^^^^^^^^^^^^^^^^^^^^^^^ File "/var/task/sqlalchemy/pool/base.py", line 1264, in _checkout fairy = _ConnectionRecord.checkout(pool) ^^^^^^^^^^^^^^^^^^^^^^^^^^^^^^^^ File "/var/task/sqlalchemy/pool/base.py", line 713, in checkout rec = pool._do_get() ^^^^^^^^^^^^^^ File "/var/task/sqlalchemy/pool/impl.py", line 179, in _do_get with util.safe_reraise(): ^^^^^^^^^^^^^^^^^^^ File "/var/task/sqlalchemy/util/langhelpers.py", line 146, in __exit__ raise exc_value.with_traceback(exc_tb) File "/var/task/sqlalchemy/pool/impl.py", line 177, in _do_get return self._create_connection() ^^^^^^^^^^^^^^^^^^^^^^^^^ File "/var/task/sqlalchemy/pool/base.py", line 390, in _create_connection return _ConnectionRecord(self) ^^^^^^^^^^^^^^^^^^^^^^^ File "/var/task/sqlalchemy/pool/base.py", line 675, in __init__ self.__connect() File "/var/task/sqlalchemy/pool/base.py", line 901, in __connect with util.safe_reraise(): ^^^^^^^^^^^^^^^^^^^ File "/var/task/sqlalchemy/util/langhelpers.py", line 146, in __exit__ raise exc_value.with_traceback(exc_tb) File "/var/task/sqlalchemy/pool/base.py", line 897, in __connect self.dbapi_connection = connection = pool._invoke_creator(self) ^^^^^^^^^^^^^^^^^^^^^^^^^^ File "/var/task/sqlalchemy/engine/create.py", line 646, in connect return dialect.connect(*cargs, **cparams) ^^^^^^^^^^^^^^^^^^^^^^^^^^^^^^^^^^ File "/var/task/sqlalchemy/engine/default.py", line 625, in connect return self.loaded_dbapi.connect(*cargs, **cparams) # type: ignore[no-any-return] # NOQA: E501 ^^^^^^^^^^^^^^^^^^^^^^^^^^^^^^^^^^^^^^^^^^^^ File "/var/task/psycopg2/__init__.py", line 121, in connect dsn = _ext.make_dsn(dsn, **kwargs) ^^^^^^^^^^^^^^^^^^^^^^^^^^^^ File "/var/task/psycopg2/extensions.py", line 167, in make_dsn parse_dsn(dsn) sqlalchemy.exc.ProgrammingError: (psycopg2.ProgrammingError) invalid dsn: invalid connection option "supa" (Background on this error at: https://sqlalche.me/e/20/f405) Python process exited with exit status: 1. The logs above can help with debugging the issue.
Apr 07 13:44:01.91
GET
500
clipbaord-e6q518n10-kagabolucky72-gmailcoms-projects.vercel.app
/
ython.py", line 14, in <module> __vc_spec.loader.exec_module(__vc_module) File "<frozen importlib._bootstrap_external>", line 999, in exec_module File "<frozen importlib._bootstrap>", line 488, in _call_with_frames_removed File "/var/task/api/index.py", line 13, in <module> from web_app import app File "/var/task/web_app.py", line 33, in <module> db_manager = DatabaseManager() ^^^^^^^^^^^^^^^^^ File "/var/task/database.py", line 56, in __init__ Base.metadata.create_all(self.engine) File "/var/task/sqlalchemy/sql/schema.py", line 5925, in create_all bind._run_ddl_visitor( File "/var/task/sqlalchemy/engine/base.py", line 3248, in _run_ddl_visitor with self.begin() as conn: ^^^^^^^^^^^^ File "/var/lang/lib/python3.12/contextlib.py", line 137, in __enter__ return next(self.gen) ^^^^^^^^^^^^^^ File "/var/task/sqlalchemy/engine/base.py", line 3238, in begin with self.connect() as conn: ^^^^^^^^^^^^^^ File "/var/task/sqlalchemy/engine/base.py", line 3274, in connect return self._connection_cls(self) ^^^^^^^^^^^^^^^^^^^^^^^^^^ File "/var/task/sqlalchemy/engine/base.py", line 148, in __init__ Connection._handle_dbapi_exception_noconnection( File "/var/task/sqlalchemy/engine/base.py", line 2439, in _handle_dbapi_exception_noconnection raise sqlalchemy_exception.with_traceback(exc_info[2]) from e File "/var/task/sqlalchemy/engine/base.py", line 146, in __init__ self._dbapi_connection = engine.raw_connection() ^^^^^^^^^^^^^^^^^^^^^^^ File "/var/task/sqlalchemy/engine/base.py", line 3298, in raw_connection return self.pool.connect() ^^^^^^^^^^^^^^^^^^^ File "/var/task/sqlalchemy/pool/base.py", line 449, in connect return _ConnectionFairy._checkout(self) ^^^^^^^^^^^^^^^^^^^^^^^^^^^^^^^^ File "/var/task/sqlalchemy/pool/base.py", line 1264, in _checkout fairy = _ConnectionRecord.checkout(pool) ^^^^^^^^^^^^^^^^^^^^^^^^^^^^^^^^ File "/var/task/sqlalchemy/pool/base.py", line 713, in checkout rec = pool._do_get() ^^^^^^^^^^^^^^ File "/var/task/sqlalchemy/pool/impl.py", line 179, in _do_get with util.safe_reraise(): ^^^^^^^^^^^^^^^^^^^ File "/var/task/sqlalchemy/util/langhelpers.py", line 146, in __exit__ raise exc_value.with_traceback(exc_tb) File "/var/task/sqlalchemy/pool/impl.py", line 177, in _do_get return self._create_connection() ^^^^^^^^^^^^^^^^^^^^^^^^^ File "/var/task/sqlalchemy/pool/base.py", line 390, in _create_connection return _ConnectionRecord(self) ^^^^^^^^^^^^^^^^^^^^^^^ File "/var/task/sqlalchemy/pool/base.py", line 675, in __init__ self.__connect() File "/var/task/sqlalchemy/pool/base.py", line 901, in __connect with util.safe_reraise(): ^^^^^^^^^^^^^^^^^^^ File "/var/task/sqlalchemy/util/langhelpers.py", line 146, in __exit__ raise exc_value.with_traceback(exc_tb) File "/var/task/sqlalchemy/pool/base.py", line 897, in __connect self.dbapi_connection = connection = pool._invoke_creator(self) ^^^^^^^^^^^^^^^^^^^^^^^^^^ File "/var/task/sqlalchemy/engine/create.py", line 646, in connect return dialect.connect(*cargs, **cparams) ^^^^^^^^^^^^^^^^^^^^^^^^^^^^^^^^^^ File "/var/task/sqlalchemy/engine/default.py", line 625, in connect return self.loaded_dbapi.connect(*cargs, **cparams) # type: ignore[no-any-return] # NOQA: E501 ^^^^^^^^^^^^^^^^^^^^^^^^^^^^^^^^^^^^^^^^^^^^ File "/var/task/psycopg2/__init__.py", line 121, in connect dsn = _ext.make_dsn(dsn, **kwargs) ^^^^^^^^^^^^^^^^^^^^^^^^^^^^ File "/var/task/psycopg2/extensions.py", line 167, in make_dsn parse_dsn(dsn) sqlalchemy.exc.ProgrammingError: (psycopg2.ProgrammingError) invalid dsn: invalid connection option "supa" (Background on this error at: https://sqlalche.me/e/20/f405) Python process exited with exit status: 1. The logs above can help with debugging the issue.
Apr 07 13:44:01.82
GET
500
clipbaord-e6q518n10-kagabolucky72-gmailcoms-projects.vercel.app
/
ython.py", line 14, in <module> __vc_spec.loader.exec_module(__vc_module) File "<frozen importlib._bootstrap_external>", line 999, in exec_module File "<frozen importlib._bootstrap>", line 488, in _call_with_frames_removed File "/var/task/api/index.py", line 13, in <module> from web_app import app File "/var/task/web_app.py", line 33, in <module> db_manager = DatabaseManager() ^^^^^^^^^^^^^^^^^ File "/var/task/database.py", line 56, in __init__ Base.metadata.create_all(self.engine) File "/var/task/sqlalchemy/sql/schema.py", line 5925, in create_all bind._run_ddl_visitor( File "/var/task/sqlalchemy/engine/base.py", line 3248, in _run_ddl_visitor with self.begin() as conn: ^^^^^^^^^^^^ File "/var/lang/lib/python3.12/contextlib.py", line 137, in __enter__ return next(self.gen) ^^^^^^^^^^^^^^ File "/var/task/sqlalchemy/engine/base.py", line 3238, in begin with self.connect() as conn: ^^^^^^^^^^^^^^ File "/var/task/sqlalchemy/engine/base.py", line 3274, in connect return self._connection_cls(self) ^^^^^^^^^^^^^^^^^^^^^^^^^^ File "/var/task/sqlalchemy/engine/base.py", line 148, in __init__ Connection._handle_dbapi_exception_noconnection( File "/var/task/sqlalchemy/engine/base.py", line 2439, in _handle_dbapi_exception_noconnection raise sqlalchemy_exception.with_traceback(exc_info[2]) from e File "/var/task/sqlalchemy/engine/base.py", line 146, in __init__ self._dbapi_connection = engine.raw_connection() ^^^^^^^^^^^^^^^^^^^^^^^ File "/var/task/sqlalchemy/engine/base.py", line 3298, in raw_connection return self.pool.connect() ^^^^^^^^^^^^^^^^^^^ File "/var/task/sqlalchemy/pool/base.py", line 449, in connect return _ConnectionFairy._checkout(self) ^^^^^^^^^^^^^^^^^^^^^^^^^^^^^^^^ File "/var/task/sqlalchemy/pool/base.py", line 1264, in _checkout fairy = _ConnectionRecord.checkout(pool) ^^^^^^^^^^^^^^^^^^^^^^^^^^^^^^^^ File "/var/task/sqlalchemy/pool/base.py", line 713, in checkout rec = pool._do_get() ^^^^^^^^^^^^^^ File "/var/task/sqlalchemy/pool/impl.py", line 179, in _do_get with util.safe_reraise(): ^^^^^^^^^^^^^^^^^^^ File "/var/task/sqlalchemy/util/langhelpers.py", line 146, in __exit__ raise exc_value.with_traceback(exc_tb) File "/var/task/sqlalchemy/pool/impl.py", line 177, in _do_get return self._create_connection() ^^^^^^^^^^^^^^^^^^^^^^^^^ File "/var/task/sqlalchemy/pool/base.py", line 390, in _create_connection return _ConnectionRecord(self) ^^^^^^^^^^^^^^^^^^^^^^^ File "/var/task/sqlalchemy/pool/base.py", line 675, in __init__ self.__connect() File "/var/task/sqlalchemy/pool/base.py", line 901, in __connect with util.safe_reraise(): ^^^^^^^^^^^^^^^^^^^ File "/var/task/sqlalchemy/util/langhelpers.py", line 146, in __exit__ raise exc_value.with_traceback(exc_tb) File "/var/task/sqlalchemy/pool/base.py", line 897, in __connect self.dbapi_connection = connection = pool._invoke_creator(self) ^^^^^^^^^^^^^^^^^^^^^^^^^^ File "/var/task/sqlalchemy/engine/create.py", line 646, in connect return dialect.connect(*cargs, **cparams) ^^^^^^^^^^^^^^^^^^^^^^^^^^^^^^^^^^ File "/var/task/sqlalchemy/engine/default.py", line 625, in connect return self.loaded_dbapi.connect(*cargs, **cparams) # type: ignore[no-any-return] # NOQA: E501 ^^^^^^^^^^^^^^^^^^^^^^^^^^^^^^^^^^^^^^^^^^^^ File "/var/task/psycopg2/__init__.py", line 121, in connect dsn = _ext.make_dsn(dsn, **kwargs) ^^^^^^^^^^^^^^^^^^^^^^^^^^^^ File "/var/task/psycopg2/extensions.py", line 167, in make_dsn parse_dsn(dsn) sqlalchemy.exc.ProgrammingError: (psycopg2.ProgrammingError) invalid dsn: invalid connection option "supa" (Background on this error at: https://sqlalche.me/e/20/f405) Python process exited with exit status: 1. The logs above can help with debugging the issue.
Apr 07 13:44:01.59
GET
500
clipbaord-e6q518n10-kagabolucky72-gmailcoms-projects.vercel.app
/
ython.py", line 14, in <module> __vc_spec.loader.exec_module(__vc_module) File "<frozen importlib._bootstrap_external>", line 999, in exec_module File "<frozen importlib._bootstrap>", line 488, in _call_with_frames_removed File "/var/task/api/index.py", line 13, in <module> from web_app import app File "/var/task/web_app.py", line 33, in <module> db_manager = DatabaseManager() ^^^^^^^^^^^^^^^^^ File "/var/task/database.py", line 56, in __init__ Base.metadata.create_all(self.engine) File "/var/task/sqlalchemy/sql/schema.py", line 5925, in create_all bind._run_ddl_visitor( File "/var/task/sqlalchemy/engine/base.py", line 3248, in _run_ddl_visitor with self.begin() as conn: ^^^^^^^^^^^^ File "/var/lang/lib/python3.12/contextlib.py", line 137, in __enter__ return next(self.gen) ^^^^^^^^^^^^^^ File "/var/task/sqlalchemy/engine/base.py", line 3238, in begin with self.connect() as conn: ^^^^^^^^^^^^^^ File "/var/task/sqlalchemy/engine/base.py", line 3274, in connect return self._connection_cls(self) ^^^^^^^^^^^^^^^^^^^^^^^^^^ File "/var/task/sqlalchemy/engine/base.py", line 148, in __init__ Connection._handle_dbapi_exception_noconnection( File "/var/task/sqlalchemy/engine/base.py", line 2439, in _handle_dbapi_exception_noconnection raise sqlalchemy_exception.with_traceback(exc_info[2]) from e File "/var/task/sqlalchemy/engine/base.py", line 146, in __init__ self._dbapi_connection = engine.raw_connection() ^^^^^^^^^^^^^^^^^^^^^^^ File "/var/task/sqlalchemy/engine/base.py", line 3298, in raw_connection return self.pool.connect() ^^^^^^^^^^^^^^^^^^^ File "/var/task/sqlalchemy/pool/base.py", line 449, in connect return _ConnectionFairy._checkout(self) ^^^^^^^^^^^^^^^^^^^^^^^^^^^^^^^^ File "/var/task/sqlalchemy/pool/base.py", line 1264, in _checkout fairy = _ConnectionRecord.checkout(pool) ^^^^^^^^^^^^^^^^^^^^^^^^^^^^^^^^ File "/var/task/sqlalchemy/pool/base.py", line 713, in checkout rec = pool._do_get() ^^^^^^^^^^^^^^ File "/var/task/sqlalchemy/pool/impl.py", line 179, in _do_get with util.safe_reraise(): ^^^^^^^^^^^^^^^^^^^ File "/var/task/sqlalchemy/util/langhelpers.py", line 146, in __exit__ raise exc_value.with_traceback(exc_tb) File "/var/task/sqlalchemy/pool/impl.py", line 177, in _do_get return self._create_connection() ^^^^^^^^^^^^^^^^^^^^^^^^^ File "/var/task/sqlalchemy/pool/base.py", line 390, in _create_connection return _ConnectionRecord(self) ^^^^^^^^^^^^^^^^^^^^^^^ File "/var/task/sqlalchemy/pool/base.py", line 675, in __init__ self.__connect() File "/var/task/sqlalchemy/pool/base.py", line 901, in __connect with util.safe_reraise(): ^^^^^^^^^^^^^^^^^^^ File "/var/task/sqlalchemy/util/langhelpers.py", line 146, in __exit__ raise exc_value.with_traceback(exc_tb) File "/var/task/sqlalchemy/pool/base.py", line 897, in __connect self.dbapi_connection = connection = pool._invoke_creator(self) ^^^^^^^^^^^^^^^^^^^^^^^^^^ File "/var/task/sqlalchemy/engine/create.py", line 646, in connect return dialect.connect(*cargs, **cparams) ^^^^^^^^^^^^^^^^^^^^^^^^^^^^^^^^^^ File "/var/task/sqlalchemy/engine/default.py", line 625, in connect return self.loaded_dbapi.connect(*cargs, **cparams) # type: ignore[no-any-return] # NOQA: E501 ^^^^^^^^^^^^^^^^^^^^^^^^^^^^^^^^^^^^^^^^^^^^ File "/var/task/psycopg2/__init__.py", line 121, in connect dsn = _ext.make_dsn(dsn, **kwargs) ^^^^^^^^^^^^^^^^^^^^^^^^^^^^ File "/var/task/psycopg2/extensions.py", line 167, in make_dsn parse_dsn(dsn) sqlalchemy.exc.ProgrammingError: (psycopg2.ProgrammingError) invalid dsn: invalid connection option "supa" (Background on this error at: https://sqlalche.me/e/20/f405) Python process exited with exit status: 1. The logs above can help with debugging the issue.
Apr 07 13:43:59.11
GET
500
clipbaord-e6q518n10-kagabolucky72-gmailcoms-projects.vercel.app
/
ython.py", line 14, in <module> __vc_spec.loader.exec_module(__vc_module) File "<frozen importlib._bootstrap_external>", line 999, in exec_module File "<frozen importlib._bootstrap>", line 488, in _call_with_frames_removed File "/var/task/api/index.py", line 13, in <module> from web_app import app File "/var/task/web_app.py", line 33, in <module> db_manager = DatabaseManager() ^^^^^^^^^^^^^^^^^ File "/var/task/database.py", line 56, in __init__ Base.metadata.create_all(self.engine) File "/var/task/sqlalchemy/sql/schema.py", line 5925, in create_all bind._run_ddl_visitor( File "/var/task/sqlalchemy/engine/base.py", line 3248, in _run_ddl_visitor with self.begin() as conn: ^^^^^^^^^^^^ File "/var/lang/lib/python3.12/contextlib.py", line 137, in __enter__ return next(self.gen) ^^^^^^^^^^^^^^ File "/var/task/sqlalchemy/engine/base.py", line 3238, in begin with self.connect() as conn: ^^^^^^^^^^^^^^ File "/var/task/sqlalchemy/engine/base.py", line 3274, in connect return self._connection_cls(self) ^^^^^^^^^^^^^^^^^^^^^^^^^^ File "/var/task/sqlalchemy/engine/base.py", line 148, in __init__ Connection._handle_dbapi_exception_noconnection( File "/var/task/sqlalchemy/engine/base.py", line 2439, in _handle_dbapi_exception_noconnection raise sqlalchemy_exception.with_traceback(exc_info[2]) from e File "/var/task/sqlalchemy/engine/base.py", line 146, in __init__ self._dbapi_connection = engine.raw_connection() ^^^^^^^^^^^^^^^^^^^^^^^ File "/var/task/sqlalchemy/engine/base.py", line 3298, in raw_connection return self.pool.connect() ^^^^^^^^^^^^^^^^^^^ File "/var/task/sqlalchemy/pool/base.py", line 449, in connect return _ConnectionFairy._checkout(self) ^^^^^^^^^^^^^^^^^^^^^^^^^^^^^^^^ File "/var/task/sqlalchemy/pool/base.py", line 1264, in _checkout fairy = _ConnectionRecord.checkout(pool) ^^^^^^^^^^^^^^^^^^^^^^^^^^^^^^^^ File "/var/task/sqlalchemy/pool/base.py", line 713, in checkout rec = pool._do_get() ^^^^^^^^^^^^^^ File "/var/task/sqlalchemy/pool/impl.py", line 179, in _do_get with util.safe_reraise(): ^^^^^^^^^^^^^^^^^^^ File "/var/task/sqlalchemy/util/langhelpers.py", line 146, in __exit__ raise exc_value.with_traceback(exc_tb) File "/var/task/sqlalchemy/pool/impl.py", line 177, in _do_get return self._create_connection() ^^^^^^^^^^^^^^^^^^^^^^^^^ File "/var/task/sqlalchemy/pool/base.py", line 390, in _create_connection return _ConnectionRecord(self) ^^^^^^^^^^^^^^^^^^^^^^^ File "/var/task/sqlalchemy/pool/base.py", line 675, in __init__ self.__connect() File "/var/task/sqlalchemy/pool/base.py", line 901, in __connect with util.safe_reraise(): ^^^^^^^^^^^^^^^^^^^ File "/var/task/sqlalchemy/util/langhelpers.py", line 146, in __exit__ raise exc_value.with_traceback(exc_tb) File "/var/task/sqlalchemy/pool/base.py", line 897, in __connect self.dbapi_connection = connection = pool._invoke_creator(self) ^^^^^^^^^^^^^^^^^^^^^^^^^^ File "/var/task/sqlalchemy/engine/create.py", line 646, in connect return dialect.connect(*cargs, **cparams) ^^^^^^^^^^^^^^^^^^^^^^^^^^^^^^^^^^ File "/var/task/sqlalchemy/engine/default.py", line 625, in connect return self.loaded_dbapi.connect(*cargs, **cparams) # type: ignore[no-any-return] # NOQA: E501 ^^^^^^^^^^^^^^^^^^^^^^^^^^^^^^^^^^^^^^^^^^^^ File "/var/task/psycopg2/__init__.py", line 121, in connect dsn = _ext.make_dsn(dsn, **kwargs) ^^^^^^^^^^^^^^^^^^^^^^^^^^^^ File "/var/task/psycopg2/extensions.py", line 167, in make_dsn parse_dsn(dsn) sqlalchemy.exc.ProgrammingError: (psycopg2.ProgrammingError) invalid dsn: invalid connection option "supa" (Background on this error at: https://sqlalche.me/e/20/f405) Python process exited with exit status: 1. The logs above can help with debugging the issue.
Apr 07 13:43:59.04
GET
500
clipbaord-e6q518n10-kagabolucky72-gmailcoms-projects.vercel.app
/
ython.py", line 14, in <module> __vc_spec.loader.exec_module(__vc_module) File "<frozen importlib._bootstrap_external>", line 999, in exec_module File "<frozen importlib._bootstrap>", line 488, in _call_with_frames_removed File "/var/task/api/index.py", line 13, in <module> from web_app import app File "/var/task/web_app.py", line 33, in <module> db_manager = DatabaseManager() ^^^^^^^^^^^^^^^^^ File "/var/task/database.py", line 56, in __init__ Base.metadata.create_all(self.engine) File "/var/task/sqlalchemy/sql/schema.py", line 5925, in create_all bind._run_ddl_visitor( File "/var/task/sqlalchemy/engine/base.py", line 3248, in _run_ddl_visitor with self.begin() as conn: ^^^^^^^^^^^^ File "/var/lang/lib/python3.12/contextlib.py", line 137, in __enter__ return next(self.gen) ^^^^^^^^^^^^^^ File "/var/task/sqlalchemy/engine/base.py", line 3238, in begin with self.connect() as conn: ^^^^^^^^^^^^^^ File "/var/task/sqlalchemy/engine/base.py", line 3274, in connect return self._connection_cls(self) ^^^^^^^^^^^^^^^^^^^^^^^^^^ File "/var/task/sqlalchemy/engine/base.py", line 148, in __init__ Connection._handle_dbapi_exception_noconnection( File "/var/task/sqlalchemy/engine/base.py", line 2439, in _handle_dbapi_exception_noconnection raise sqlalchemy_exception.with_traceback(exc_info[2]) from e File "/var/task/sqlalchemy/engine/base.py", line 146, in __init__ self._dbapi_connection = engine.raw_connection() ^^^^^^^^^^^^^^^^^^^^^^^ File "/var/task/sqlalchemy/engine/base.py", line 3298, in raw_connection return self.pool.connect() ^^^^^^^^^^^^^^^^^^^ File "/var/task/sqlalchemy/pool/base.py", line 449, in connect return _ConnectionFairy._checkout(self) ^^^^^^^^^^^^^^^^^^^^^^^^^^^^^^^^ File "/var/task/sqlalchemy/pool/base.py", line 1264, in _checkout fairy = _ConnectionRecord.checkout(pool) ^^^^^^^^^^^^^^^^^^^^^^^^^^^^^^^^ File "/var/task/sqlalchemy/pool/base.py", line 713, in checkout rec = pool._do_get() ^^^^^^^^^^^^^^ File "/var/task/sqlalchemy/pool/impl.py", line 179, in _do_get with util.safe_reraise(): ^^^^^^^^^^^^^^^^^^^ File "/var/task/sqlalchemy/util/langhelpers.py", line 146, in __exit__ raise exc_value.with_traceback(exc_tb) File "/var/task/sqlalchemy/pool/impl.py", line 177, in _do_get return self._create_connection() ^^^^^^^^^^^^^^^^^^^^^^^^^ File "/var/task/sqlalchemy/pool/base.py", line 390, in _create_connection return _ConnectionRecord(self) ^^^^^^^^^^^^^^^^^^^^^^^ File "/var/task/sqlalchemy/pool/base.py", line 675, in __init__ self.__connect() File "/var/task/sqlalchemy/pool/base.py", line 901, in __connect with util.safe_reraise(): ^^^^^^^^^^^^^^^^^^^ File "/var/task/sqlalchemy/util/langhelpers.py", line 146, in __exit__ raise exc_value.with_traceback(exc_tb) File "/var/task/sqlalchemy/pool/base.py", line 897, in __connect self.dbapi_connection = connection = pool._invoke_creator(self) ^^^^^^^^^^^^^^^^^^^^^^^^^^ File "/var/task/sqlalchemy/engine/create.py", line 646, in connect return dialect.connect(*cargs, **cparams) ^^^^^^^^^^^^^^^^^^^^^^^^^^^^^^^^^^ File "/var/task/sqlalchemy/engine/default.py", line 625, in connect return self.loaded_dbapi.connect(*cargs, **cparams) # type: ignore[no-any-return] # NOQA: E501 ^^^^^^^^^^^^^^^^^^^^^^^^^^^^^^^^^^^^^^^^^^^^ File "/var/task/psycopg2/__init__.py", line 121, in connect dsn = _ext.make_dsn(dsn, **kwargs) ^^^^^^^^^^^^^^^^^^^^^^^^^^^^ File "/var/task/psycopg2/extensions.py", line 167, in make_dsn parse_dsn(dsn) sqlalchemy.exc.ProgrammingError: (psycopg2.ProgrammingError) invalid dsn: invalid connection option "supa" (Background on this error at: https://sqlalche.me/e/20/f405) Python process exited with exit status: 1. The logs above can help with debugging the issue.
Apr 07 13:43:56.76
GET
500
clipbaord-e6q518n10-kagabolucky72-gmailcoms-projects.vercel.app
/
ython.py", line 14, in <module> __vc_spec.loader.exec_module(__vc_module) File "<frozen importlib._bootstrap_external>", line 999, in exec_module File "<frozen importlib._bootstrap>", line 488, in _call_with_frames_removed File "/var/task/api/index.py", line 13, in <module> from web_app import app File "/var/task/web_app.py", line 33, in <module> db_manager = DatabaseManager() ^^^^^^^^^^^^^^^^^ File "/var/task/database.py", line 56, in __init__ Base.metadata.create_all(self.engine) File "/var/task/sqlalchemy/sql/schema.py", line 5925, in create_all bind._run_ddl_visitor( File "/var/task/sqlalchemy/engine/base.py", line 3248, in _run_ddl_visitor with self.begin() as conn: ^^^^^^^^^^^^ File "/var/lang/lib/python3.12/contextlib.py", line 137, in __enter__ return next(self.gen) ^^^^^^^^^^^^^^ File "/var/task/sqlalchemy/engine/base.py", line 3238, in begin with self.connect() as conn: ^^^^^^^^^^^^^^ File "/var/task/sqlalchemy/engine/base.py", line 3274, in connect return self._connection_cls(self) ^^^^^^^^^^^^^^^^^^^^^^^^^^ File "/var/task/sqlalchemy/engine/base.py", line 148, in __init__ Connection._handle_dbapi_exception_noconnection( File "/var/task/sqlalchemy/engine/base.py", line 2439, in _handle_dbapi_exception_noconnection raise sqlalchemy_exception.with_traceback(exc_info[2]) from e File "/var/task/sqlalchemy/engine/base.py", line 146, in __init__ self._dbapi_connection = engine.raw_connection() ^^^^^^^^^^^^^^^^^^^^^^^ File "/var/task/sqlalchemy/engine/base.py", line 3298, in raw_connection return self.pool.connect() ^^^^^^^^^^^^^^^^^^^ File "/var/task/sqlalchemy/pool/base.py", line 449, in connect return _ConnectionFairy._checkout(self) ^^^^^^^^^^^^^^^^^^^^^^^^^^^^^^^^ File "/var/task/sqlalchemy/pool/base.py", line 1264, in _checkout fairy = _ConnectionRecord.checkout(pool) ^^^^^^^^^^^^^^^^^^^^^^^^^^^^^^^^ File "/var/task/sqlalchemy/pool/base.py", line 713, in checkout rec = pool._do_get() ^^^^^^^^^^^^^^ File "/var/task/sqlalchemy/pool/impl.py", line 179, in _do_get with util.safe_reraise(): ^^^^^^^^^^^^^^^^^^^ File "/var/task/sqlalchemy/util/langhelpers.py", line 146, in __exit__ raise exc_value.with_traceback(exc_tb) File "/var/task/sqlalchemy/pool/impl.py", line 177, in _do_get return self._create_connection() ^^^^^^^^^^^^^^^^^^^^^^^^^ File "/var/task/sqlalchemy/pool/base.py", line 390, in _create_connection return _ConnectionRecord(self) ^^^^^^^^^^^^^^^^^^^^^^^ File "/var/task/sqlalchemy/pool/base.py", line 675, in __init__ self.__connect() File "/var/task/sqlalchemy/pool/base.py", line 901, in __connect with util.safe_reraise(): ^^^^^^^^^^^^^^^^^^^ File "/var/task/sqlalchemy/util/langhelpers.py", line 146, in __exit__ raise exc_value.with_traceback(exc_tb) File "/var/task/sqlalchemy/pool/base.py", line 897, in __connect self.dbapi_connection = connection = pool._invoke_creator(self) ^^^^^^^^^^^^^^^^^^^^^^^^^^ File "/var/task/sqlalchemy/engine/create.py", line 646, in connect return dialect.connect(*cargs, **cparams) ^^^^^^^^^^^^^^^^^^^^^^^^^^^^^^^^^^ File "/var/task/sqlalchemy/engine/default.py", line 625, in connect return self.loaded_dbapi.connect(*cargs, **cparams) # type: ignore[no-any-return] # NOQA: E501 ^^^^^^^^^^^^^^^^^^^^^^^^^^^^^^^^^^^^^^^^^^^^ File "/var/task/psycopg2/__init__.py", line 121, in connect dsn = _ext.make_dsn(dsn, **kwargs) ^^^^^^^^^^^^^^^^^^^^^^^^^^^^ File "/var/task/psycopg2/extensions.py", line 167, in make_dsn parse_dsn(dsn) sqlalchemy.exc.ProgrammingError: (psycopg2.ProgrammingError) invalid dsn: invalid connection option "supa" (Background on this error at: https://sqlalche.me/e/20/f405) Python process exited with exit status: 1. The logs above can help with debugging the issue.
Apr 07 13:43:56.67
GET
500
clipbaord-e6q518n10-kagabolucky72-gmailcoms-projects.vercel.app
/
ython.py", line 14, in <module> __vc_spec.loader.exec_module(__vc_module) File "<frozen importlib._bootstrap_external>", line 999, in exec_module File "<frozen importlib._bootstrap>", line 488, in _call_with_frames_removed File "/var/task/api/index.py", line 13, in <module> from web_app import app File "/var/task/web_app.py", line 33, in <module> db_manager = DatabaseManager() ^^^^^^^^^^^^^^^^^ File "/var/task/database.py", line 56, in __init__ Base.metadata.create_all(self.engine) File "/var/task/sqlalchemy/sql/schema.py", line 5925, in create_all bind._run_ddl_visitor( File "/var/task/sqlalchemy/engine/base.py", line 3248, in _run_ddl_visitor with self.begin() as conn: ^^^^^^^^^^^^ File "/var/lang/lib/python3.12/contextlib.py", line 137, in __enter__ return next(self.gen) ^^^^^^^^^^^^^^ File "/var/task/sqlalchemy/engine/base.py", line 3238, in begin with self.connect() as conn: ^^^^^^^^^^^^^^ File "/var/task/sqlalchemy/engine/base.py", line 3274, in connect return self._connection_cls(self) ^^^^^^^^^^^^^^^^^^^^^^^^^^ File "/var/task/sqlalchemy/engine/base.py", line 148, in __init__ Connection._handle_dbapi_exception_noconnection( File "/var/task/sqlalchemy/engine/base.py", line 2439, in _handle_dbapi_exception_noconnection raise sqlalchemy_exception.with_traceback(exc_info[2]) from e File "/var/task/sqlalchemy/engine/base.py", line 146, in __init__ self._dbapi_connection = engine.raw_connection() ^^^^^^^^^^^^^^^^^^^^^^^ File "/var/task/sqlalchemy/engine/base.py", line 3298, in raw_connection return self.pool.connect() ^^^^^^^^^^^^^^^^^^^ File "/var/task/sqlalchemy/pool/base.py", line 449, in connect return _ConnectionFairy._checkout(self) ^^^^^^^^^^^^^^^^^^^^^^^^^^^^^^^^ File "/var/task/sqlalchemy/pool/base.py", line 1264, in _checkout fairy = _ConnectionRecord.checkout(pool) ^^^^^^^^^^^^^^^^^^^^^^^^^^^^^^^^ File "/var/task/sqlalchemy/pool/base.py", line 713, in checkout rec = pool._do_get() ^^^^^^^^^^^^^^ File "/var/task/sqlalchemy/pool/impl.py", line 179, in _do_get with util.safe_reraise(): ^^^^^^^^^^^^^^^^^^^ File "/var/task/sqlalchemy/util/langhelpers.py", line 146, in __exit__ raise exc_value.with_traceback(exc_tb) File "/var/task/sqlalchemy/pool/impl.py", line 177, in _do_get return self._create_connection() ^^^^^^^^^^^^^^^^^^^^^^^^^ File "/var/task/sqlalchemy/pool/base.py", line 390, in _create_connection return _ConnectionRecord(self) ^^^^^^^^^^^^^^^^^^^^^^^ File "/var/task/sqlalchemy/pool/base.py", line 675, in __init__ self.__connect() File "/var/task/sqlalchemy/pool/base.py", line 901, in __connect with util.safe_reraise(): ^^^^^^^^^^^^^^^^^^^ File "/var/task/sqlalchemy/util/langhelpers.py", line 146, in __exit__ raise exc_value.with_traceback(exc_tb) File "/var/task/sqlalchemy/pool/base.py", line 897, in __connect self.dbapi_connection = connection = pool._invoke_creator(self) ^^^^^^^^^^^^^^^^^^^^^^^^^^ File "/var/task/sqlalchemy/engine/create.py", line 646, in connect return dialect.connect(*cargs, **cparams) ^^^^^^^^^^^^^^^^^^^^^^^^^^^^^^^^^^ File "/var/task/sqlalchemy/engine/default.py", line 625, in connect return self.loaded_dbapi.connect(*cargs, **cparams) # type: ignore[no-any-return] # NOQA: E501 ^^^^^^^^^^^^^^^^^^^^^^^^^^^^^^^^^^^^^^^^^^^^ File "/var/task/psycopg2/__init__.py", line 121, in connect dsn = _ext.make_dsn(dsn, **kwargs) ^^^^^^^^^^^^^^^^^^^^^^^^^^^^ File "/var/task/psycopg2/extensions.py", line 167, in make_dsn parse_dsn(dsn) sqlalchemy.exc.ProgrammingError: (psycopg2.ProgrammingError) invalid dsn: invalid connection option "supa" (Background on this error at: https://sqlalche.me/e/20/f405) Python process exited with exit status: 1. The logs above can help with debugging the issue.
No more logs to show with